Workbook

Sheet Electrical QC Checklist
A1: Applicable | B1: Incorporated | C1: Confirmed | D1: Electrical QC Checklist
D2: Project # | E2: ='Project Information'!B3 -> 25999999 | F2: ='Project Information'!B2 -> EXAMPLE PROJECT NAME | G2: ='Project Information'!B4 -> 45950 | H2: Filters
D3: Topic | E3: Category | F3: Item | G3: Notes | H3: Standard | I3: Healthcare | J3: Sports | K3: Site Plan | L3: Food Service / Kitchen | M3: Demolition / Renovation | N3: Utility Service Entrance | O3: Duct Bank (Feeder or Utility Service Entrance) | P3: ATS | Q3: Exterior Generator or Fuel Tank | R3: Indoor Generator Room | S3: Exterior Lighting | T3: Helipad | U3: Elevator / Escalator | V3: Fire Pump | W3: Fire Command Center | X3: Emergency Radio Communication System | Y3: Fire Alarm | Z3: FILTERING
A4: FALSE | B4: FALSE | C4: FALSE | D4: General | E4: Specifications | F4: All applicable specification sections included | H4: ='Project Information'!$B$6*'Filters (EPIC)'!B3 -> 1 | I4: ='Project Information'!$B$7*'Filters (EPIC)'!C3 -> 0 | J4: ='Project Information'!$B$8*'Filters (EPIC)'!D3 -> 0 | K4: ='Project Information'!$B$9*'Filters (EPIC)'!E3 -> 0 | L4: ='Project Information'!$B$10*'Filters (EPIC)'!F3 -> 0 | M4: ='Project Information'!$B$11*'Filters (EPIC)'!G3 -> 0 | N4: ='Project Information'!$B$12*'Filters (EPIC)'!H3 -> 0 | O4: ='Project Information'!$B$13*'Filters (EPIC)'!I3 -> 0 | P4: ='Project Information'!$B$14*'Filters (EPIC)'!J3 -> 0 | Q4: ='Project Information'!$B$15*'Filters (EPIC)'!K3 -> 0 | R4: ='Project Information'!$B$16*'Filters (EPIC)'!L3 -> 0 | S4: ='Project Information'!$B$17*'Filters (EPIC)'!M3 -> 0 | T4: ='Project Information'!$B$18*'Filters (EPIC)'!N3 -> 0 | U4: ='Project Information'!$B$19*'Filters (EPIC)'!O3 -> 0 | V4: ='Project Information'!$B$20*'Filters (EPIC)'!P3 -> 0 | W4: ='Project Information'!$B$21*'Filters (EPIC)'!Q3 -> 0 | X4: ='Project Information'!$B$22*'Filters (EPIC)'!R3 -> 0 | Y4: ='Project Information'!$B$23*'Filters (EPIC)'!S3 -> 0 | Z4: =OR(COUNTIF(H4:Y4,1)>0) -> TRUE
A5: FALSE | B5: FALSE | C5: FALSE | D5: General | E5: Specifications | F5: Specifications are edited for project specific scope | H5: ='Project Information'!$B$6*'Filters (EPIC)'!B4 -> 1 | I5: ='Project Information'!$B$7*'Filters (EPIC)'!C4 -> 0 | J5: ='Project Information'!$B$8*'Filters (EPIC)'!D4 -> 0 | K5: ='Project Information'!$B$9*'Filters (EPIC)'!E4 -> 0 | L5: ='Project Information'!$B$10*'Filters (EPIC)'!F4 -> 0 | M5: ='Project Information'!$B$11*'Filters (EPIC)'!G4 -> 0 | N5: ='Project Information'!$B$12*'Filters (EPIC)'!H4 -> 0 | O5: ='Project Information'!$B$13*'Filters (EPIC)'!I4 -> 0 | P5: ='Project Information'!$B$14*'Filters (EPIC)'!J4 -> 0 | Q5: ='Project Information'!$B$15*'Filters (EPIC)'!K4 -> 0 | R5: ='Project Information'!$B$16*'Filters (EPIC)'!L4 -> 0 | S5: ='Project Information'!$B$17*'Filters (EPIC)'!M4 -> 0 | T5: ='Project Information'!$B$18*'Filters (EPIC)'!N4 -> 0 | U5: ='Project Information'!$B$19*'Filters (EPIC)'!O4 -> 0 | V5: ='Project Information'!$B$20*'Filters (EPIC)'!P4 -> 0 | W5: ='Project Information'!$B$21*'Filters (EPIC)'!Q4 -> 0 | X5: ='Project Information'!$B$22*'Filters (EPIC)'!R4 -> 0 | Y5: ='Project Information'!$B$23*'Filters (EPIC)'!S4 -> 0 | Z5: =OR(COUNTIF(H5:Y5,1)>0) -> TRUE
A6: FALSE | B6: FALSE | C6: FALSE | D6: General | E6: Specifications | F6: Specifications identify applicable codes including energy code(s) | H6: ='Project Information'!$B$6*'Filters (EPIC)'!B5 -> 1 | I6: ='Project Information'!$B$7*'Filters (EPIC)'!C5 -> 0 | J6: ='Project Information'!$B$8*'Filters (EPIC)'!D5 -> 0 | K6: ='Project Information'!$B$9*'Filters (EPIC)'!E5 -> 0 | L6: ='Project Information'!$B$10*'Filters (EPIC)'!F5 -> 0 | M6: ='Project Information'!$B$11*'Filters (EPIC)'!G5 -> 0 | N6: ='Project Information'!$B$12*'Filters (EPIC)'!H5 -> 0 | O6: ='Project Information'!$B$13*'Filters (EPIC)'!I5 -> 0 | P6: ='Project Information'!$B$14*'Filters (EPIC)'!J5 -> 0 | Q6: ='Project Information'!$B$15*'Filters (EPIC)'!K5 -> 0 | R6: ='Project Information'!$B$16*'Filters (EPIC)'!L5 -> 0 | S6: ='Project Information'!$B$17*'Filters (EPIC)'!M5 -> 0 | T6: ='Project Information'!$B$18*'Filters (EPIC)'!N5 -> 0 | U6: ='Project Information'!$B$19*'Filters (EPIC)'!O5 -> 0 | V6: ='Project Information'!$B$20*'Filters (EPIC)'!P5 -> 0 | W6: ='Project Information'!$B$21*'Filters (EPIC)'!Q5 -> 0 | X6: ='Project Information'!$B$22*'Filters (EPIC)'!R5 -> 0 | Y6: ='Project Information'!$B$23*'Filters (EPIC)'!S5 -> 0 | Z6: =OR(COUNTIF(H6:Y6,1)>0) -> TRUE
A7: FALSE | B7: FALSE | C7: FALSE | D7: General | E7: Specifications | F7: Specifications for conductors (copper, aluminum, or both) are consistent with schedules and owner direction | H7: ='Project Information'!$B$6*'Filters (EPIC)'!B6 -> 1 | I7: ='Project Information'!$B$7*'Filters (EPIC)'!C6 -> 0 | J7: ='Project Information'!$B$8*'Filters (EPIC)'!D6 -> 0 | K7: ='Project Information'!$B$9*'Filters (EPIC)'!E6 -> 0 | L7: ='Project Information'!$B$10*'Filters (EPIC)'!F6 -> 0 | M7: ='Project Information'!$B$11*'Filters (EPIC)'!G6 -> 0 | N7: ='Project Information'!$B$12*'Filters (EPIC)'!H6 -> 0 | O7: ='Project Information'!$B$13*'Filters (EPIC)'!I6 -> 0 | P7: ='Project Information'!$B$14*'Filters (EPIC)'!J6 -> 0 | Q7: ='Project Information'!$B$15*'Filters (EPIC)'!K6 -> 0 | R7: ='Project Information'!$B$16*'Filters (EPIC)'!L6 -> 0 | S7: ='Project Information'!$B$17*'Filters (EPIC)'!M6 -> 0 | T7: ='Project Information'!$B$18*'Filters (EPIC)'!N6 -> 0 | U7: ='Project Information'!$B$19*'Filters (EPIC)'!O6 -> 0 | V7: ='Project Information'!$B$20*'Filters (EPIC)'!P6 -> 0 | W7: ='Project Information'!$B$21*'Filters (EPIC)'!Q6 -> 0 | X7: ='Project Information'!$B$22*'Filters (EPIC)'!R6 -> 0 | Y7: ='Project Information'!$B$23*'Filters (EPIC)'!S6 -> 0 | Z7: =OR(COUNTIF(H7:Y7,1)>0) -> TRUE
A8: FALSE | B8: FALSE | C8: FALSE | D8: General | E8: Renovation | F8: Construction sequence / phasing is considered and temporary electrical equipment or requirements are identified. | H8: ='Project Information'!$B$6*'Filters (EPIC)'!B7 -> 0 | I8: ='Project Information'!$B$7*'Filters (EPIC)'!C7 -> 0 | J8: ='Project Information'!$B$8*'Filters (EPIC)'!D7 -> 0 | K8: ='Project Information'!$B$9*'Filters (EPIC)'!E7 -> 0 | L8: ='Project Information'!$B$10*'Filters (EPIC)'!F7 -> 0 | M8: ='Project Information'!$B$11*'Filters (EPIC)'!G7 -> 0 | N8: ='Project Information'!$B$12*'Filters (EPIC)'!H7 -> 0 | O8: ='Project Information'!$B$13*'Filters (EPIC)'!I7 -> 0 | P8: ='Project Information'!$B$14*'Filters (EPIC)'!J7 -> 0 | Q8: ='Project Information'!$B$15*'Filters (EPIC)'!K7 -> 0 | R8: ='Project Information'!$B$16*'Filters (EPIC)'!L7 -> 0 | S8: ='Project Information'!$B$17*'Filters (EPIC)'!M7 -> 0 | T8: ='Project Information'!$B$18*'Filters (EPIC)'!N7 -> 0 | U8: ='Project Information'!$B$19*'Filters (EPIC)'!O7 -> 0 | V8: ='Project Information'!$B$20*'Filters (EPIC)'!P7 -> 0 | W8: ='Project Information'!$B$21*'Filters (EPIC)'!Q7 -> 0 | X8: ='Project Information'!$B$22*'Filters (EPIC)'!R7 -> 0 | Y8: ='Project Information'!$B$23*'Filters (EPIC)'!S7 -> 0 | Z8: =OR(COUNTIF(H8:Y8,1)>0) -> FALSE
A9: FALSE | B9: FALSE | C9: FALSE | D9: General | E9: Renovation | F9: Existing to remain, existing to be removed, new work is clearly identified | H9: ='Project Information'!$B$6*'Filters (EPIC)'!B8 -> 0 | I9: ='Project Information'!$B$7*'Filters (EPIC)'!C8 -> 0 | J9: ='Project Information'!$B$8*'Filters (EPIC)'!D8 -> 0 | K9: ='Project Information'!$B$9*'Filters (EPIC)'!E8 -> 0 | L9: ='Project Information'!$B$10*'Filters (EPIC)'!F8 -> 0 | M9: ='Project Information'!$B$11*'Filters (EPIC)'!G8 -> 0 | N9: ='Project Information'!$B$12*'Filters (EPIC)'!H8 -> 0 | O9: ='Project Information'!$B$13*'Filters (EPIC)'!I8 -> 0 | P9: ='Project Information'!$B$14*'Filters (EPIC)'!J8 -> 0 | Q9: ='Project Information'!$B$15*'Filters (EPIC)'!K8 -> 0 | R9: ='Project Information'!$B$16*'Filters (EPIC)'!L8 -> 0 | S9: ='Project Information'!$B$17*'Filters (EPIC)'!M8 -> 0 | T9: ='Project Information'!$B$18*'Filters (EPIC)'!N8 -> 0 | U9: ='Project Information'!$B$19*'Filters (EPIC)'!O8 -> 0 | V9: ='Project Information'!$B$20*'Filters (EPIC)'!P8 -> 0 | W9: ='Project Information'!$B$21*'Filters (EPIC)'!Q8 -> 0 | X9: ='Project Information'!$B$22*'Filters (EPIC)'!R8 -> 0 | Y9: ='Project Information'!$B$23*'Filters (EPIC)'!S8 -> 0 | Z9: =OR(COUNTIF(H9:Y9,1)>0) -> FALSE
A10: FALSE | B10: FALSE | C10: FALSE | D10: General | E10: Renovation | F10: Standard ICRA notes are included for healthcare projects | H10: ='Project Information'!$B$6*'Filters (EPIC)'!B9 -> 0 | I10: ='Project Information'!$B$7*'Filters (EPIC)'!C9 -> 0 | J10: ='Project Information'!$B$8*'Filters (EPIC)'!D9 -> 0 | K10: ='Project Information'!$B$9*'Filters (EPIC)'!E9 -> 0 | L10: ='Project Information'!$B$10*'Filters (EPIC)'!F9 -> 0 | M10: ='Project Information'!$B$11*'Filters (EPIC)'!G9 -> 0 | N10: ='Project Information'!$B$12*'Filters (EPIC)'!H9 -> 0 | O10: ='Project Information'!$B$13*'Filters (EPIC)'!I9 -> 0 | P10: ='Project Information'!$B$14*'Filters (EPIC)'!J9 -> 0 | Q10: ='Project Information'!$B$15*'Filters (EPIC)'!K9 -> 0 | R10: ='Project Information'!$B$16*'Filters (EPIC)'!L9 -> 0 | S10: ='Project Information'!$B$17*'Filters (EPIC)'!M9 -> 0 | T10: ='Project Information'!$B$18*'Filters (EPIC)'!N9 -> 0 | U10: ='Project Information'!$B$19*'Filters (EPIC)'!O9 -> 0 | V10: ='Project Information'!$B$20*'Filters (EPIC)'!P9 -> 0 | W10: ='Project Information'!$B$21*'Filters (EPIC)'!Q9 -> 0 | X10: ='Project Information'!$B$22*'Filters (EPIC)'!R9 -> 0 | Y10: ='Project Information'!$B$23*'Filters (EPIC)'!S9 -> 0 | Z10: =OR(COUNTIF(H10:Y10,1)>0) -> FALSE
A11: FALSE | B11: FALSE | C11: FALSE | D11: General | E11: Renovation | F11: Demolition plans clearly identify equipment/scope as “existing to remain” or “existing to be removed” | H11: ='Project Information'!$B$6*'Filters (EPIC)'!B10 -> 0 | I11: ='Project Information'!$B$7*'Filters (EPIC)'!C10 -> 0 | J11: ='Project Information'!$B$8*'Filters (EPIC)'!D10 -> 0 | K11: ='Project Information'!$B$9*'Filters (EPIC)'!E10 -> 0 | L11: ='Project Information'!$B$10*'Filters (EPIC)'!F10 -> 0 | M11: ='Project Information'!$B$11*'Filters (EPIC)'!G10 -> 0 | N11: ='Project Information'!$B$12*'Filters (EPIC)'!H10 -> 0 | O11: ='Project Information'!$B$13*'Filters (EPIC)'!I10 -> 0 | P11: ='Project Information'!$B$14*'Filters (EPIC)'!J10 -> 0 | Q11: ='Project Information'!$B$15*'Filters (EPIC)'!K10 -> 0 | R11: ='Project Information'!$B$16*'Filters (EPIC)'!L10 -> 0 | S11: ='Project Information'!$B$17*'Filters (EPIC)'!M10 -> 0 | T11: ='Project Information'!$B$18*'Filters (EPIC)'!N10 -> 0 | U11: ='Project Information'!$B$19*'Filters (EPIC)'!O10 -> 0 | V11: ='Project Information'!$B$20*'Filters (EPIC)'!P10 -> 0 | W11: ='Project Information'!$B$21*'Filters (EPIC)'!Q10 -> 0 | X11: ='Project Information'!$B$22*'Filters (EPIC)'!R10 -> 0 | Y11: ='Project Information'!$B$23*'Filters (EPIC)'!S10 -> 0 | Z11: =OR(COUNTIF(H11:Y11,1)>0) -> FALSE
A12: FALSE | B12: FALSE | C12: FALSE | D12: General | E12: Renovation | F12: Equipment to be turned over to Owner is defined | H12: ='Project Information'!$B$6*'Filters (EPIC)'!B11 -> 0 | I12: ='Project Information'!$B$7*'Filters (EPIC)'!C11 -> 0 | J12: ='Project Information'!$B$8*'Filters (EPIC)'!D11 -> 0 | K12: ='Project Information'!$B$9*'Filters (EPIC)'!E11 -> 0 | L12: ='Project Information'!$B$10*'Filters (EPIC)'!F11 -> 0 | M12: ='Project Information'!$B$11*'Filters (EPIC)'!G11 -> 0 | N12: ='Project Information'!$B$12*'Filters (EPIC)'!H11 -> 0 | O12: ='Project Information'!$B$13*'Filters (EPIC)'!I11 -> 0 | P12: ='Project Information'!$B$14*'Filters (EPIC)'!J11 -> 0 | Q12: ='Project Information'!$B$15*'Filters (EPIC)'!K11 -> 0 | R12: ='Project Information'!$B$16*'Filters (EPIC)'!L11 -> 0 | S12: ='Project Information'!$B$17*'Filters (EPIC)'!M11 -> 0 | T12: ='Project Information'!$B$18*'Filters (EPIC)'!N11 -> 0 | U12: ='Project Information'!$B$19*'Filters (EPIC)'!O11 -> 0 | V12: ='Project Information'!$B$20*'Filters (EPIC)'!P11 -> 0 | W12: ='Project Information'!$B$21*'Filters (EPIC)'!Q11 -> 0 | X12: ='Project Information'!$B$22*'Filters (EPIC)'!R11 -> 0 | Y12: ='Project Information'!$B$23*'Filters (EPIC)'!S11 -> 0 | Z12: =OR(COUNTIF(H12:Y12,1)>0) -> FALSE
A13: FALSE | B13: FALSE | C13: FALSE | D13: General | E13: Environmental | F13: Requirements for bracing and certification are designated based on building location, use, seismic category and importance factor | H13: ='Project Information'!$B$6*'Filters (EPIC)'!B12 -> 1 | I13: ='Project Information'!$B$7*'Filters (EPIC)'!C12 -> 0 | J13: ='Project Information'!$B$8*'Filters (EPIC)'!D12 -> 0 | K13: ='Project Information'!$B$9*'Filters (EPIC)'!E12 -> 0 | L13: ='Project Information'!$B$10*'Filters (EPIC)'!F12 -> 0 | M13: ='Project Information'!$B$11*'Filters (EPIC)'!G12 -> 0 | N13: ='Project Information'!$B$12*'Filters (EPIC)'!H12 -> 0 | O13: ='Project Information'!$B$13*'Filters (EPIC)'!I12 -> 0 | P13: ='Project Information'!$B$14*'Filters (EPIC)'!J12 -> 0 | Q13: ='Project Information'!$B$15*'Filters (EPIC)'!K12 -> 0 | R13: ='Project Information'!$B$16*'Filters (EPIC)'!L12 -> 0 | S13: ='Project Information'!$B$17*'Filters (EPIC)'!M12 -> 0 | T13: ='Project Information'!$B$18*'Filters (EPIC)'!N12 -> 0 | U13: ='Project Information'!$B$19*'Filters (EPIC)'!O12 -> 0 | V13: ='Project Information'!$B$20*'Filters (EPIC)'!P12 -> 0 | W13: ='Project Information'!$B$21*'Filters (EPIC)'!Q12 -> 0 | X13: ='Project Information'!$B$22*'Filters (EPIC)'!R12 -> 0 | Y13: ='Project Information'!$B$23*'Filters (EPIC)'!S12 -> 0 | Z13: =OR(COUNTIF(H13:Y13,1)>0) -> TRUE
A14: FALSE | B14: FALSE | C14: FALSE | D14: General | E14: Environmental | F14: For hurricane zones, design wind speeds for risk category III and IV building are designated for exterior lighting, helipad lighting , and PV systems | H14: ='Project Information'!$B$6*'Filters (EPIC)'!B13 -> 1 | I14: ='Project Information'!$B$7*'Filters (EPIC)'!C13 -> 0 | J14: ='Project Information'!$B$8*'Filters (EPIC)'!D13 -> 0 | K14: ='Project Information'!$B$9*'Filters (EPIC)'!E13 -> 0 | L14: ='Project Information'!$B$10*'Filters (EPIC)'!F13 -> 0 | M14: ='Project Information'!$B$11*'Filters (EPIC)'!G13 -> 0 | N14: ='Project Information'!$B$12*'Filters (EPIC)'!H13 -> 0 | O14: ='Project Information'!$B$13*'Filters (EPIC)'!I13 -> 0 | P14: ='Project Information'!$B$14*'Filters (EPIC)'!J13 -> 0 | Q14: ='Project Information'!$B$15*'Filters (EPIC)'!K13 -> 0 | R14: ='Project Information'!$B$16*'Filters (EPIC)'!L13 -> 0 | S14: ='Project Information'!$B$17*'Filters (EPIC)'!M13 -> 0 | T14: ='Project Information'!$B$18*'Filters (EPIC)'!N13 -> 0 | U14: ='Project Information'!$B$19*'Filters (EPIC)'!O13 -> 0 | V14: ='Project Information'!$B$20*'Filters (EPIC)'!P13 -> 0 | W14: ='Project Information'!$B$21*'Filters (EPIC)'!Q13 -> 0 | X14: ='Project Information'!$B$22*'Filters (EPIC)'!R13 -> 0 | Y14: ='Project Information'!$B$23*'Filters (EPIC)'!S13 -> 0 | Z14: =OR(COUNTIF(H14:Y14,1)>0) -> TRUE
A15: FALSE | B15: FALSE | C15: FALSE | D15: General | E15: Environmental | F15: For high ambient temperature areas, capacity of generators and/or exterior transformers has been derated | H15: ='Project Information'!$B$6*'Filters (EPIC)'!B14 -> 1 | I15: ='Project Information'!$B$7*'Filters (EPIC)'!C14 -> 0 | J15: ='Project Information'!$B$8*'Filters (EPIC)'!D14 -> 0 | K15: ='Project Information'!$B$9*'Filters (EPIC)'!E14 -> 0 | L15: ='Project Information'!$B$10*'Filters (EPIC)'!F14 -> 0 | M15: ='Project Information'!$B$11*'Filters (EPIC)'!G14 -> 0 | N15: ='Project Information'!$B$12*'Filters (EPIC)'!H14 -> 0 | O15: ='Project Information'!$B$13*'Filters (EPIC)'!I14 -> 0 | P15: ='Project Information'!$B$14*'Filters (EPIC)'!J14 -> 0 | Q15: ='Project Information'!$B$15*'Filters (EPIC)'!K14 -> 0 | R15: ='Project Information'!$B$16*'Filters (EPIC)'!L14 -> 0 | S15: ='Project Information'!$B$17*'Filters (EPIC)'!M14 -> 0 | T15: ='Project Information'!$B$18*'Filters (EPIC)'!N14 -> 0 | U15: ='Project Information'!$B$19*'Filters (EPIC)'!O14 -> 0 | V15: ='Project Information'!$B$20*'Filters (EPIC)'!P14 -> 0 | W15: ='Project Information'!$B$21*'Filters (EPIC)'!Q14 -> 0 | X15: ='Project Information'!$B$22*'Filters (EPIC)'!R14 -> 0 | Y15: ='Project Information'!$B$23*'Filters (EPIC)'!S14 -> 0 | Z15: =OR(COUNTIF(H15:Y15,1)>0) -> TRUE
... A200: FALSE | B200: FALSE | C200: FALSE | D200: Power Distribution Diagrams and Risers | E200: Power Distribution Diagrams | F200: ATS pole configuration is coordinated with generator grounding approach (i.e. where generator neutral is grounded, provide 3pole/4 pole switches; where generator neutral is ungrounded, provide 3 pole/3 pole SN switches) | H200: ='Project Information'!$B$6*'Filters (EPIC)'!B199 -> 0 | I200: ='Project Information'!$B$7*'Filters (EPIC)'!C199 -> 0 | J200: ='Project Information'!$B$8*'Filters (EPIC)'!D199 -> 0 | K200: ='Project Information'!$B$9*'Filters (EPIC)'!E199 -> 0 | L200: ='Project Information'!$B$10*'Filters (EPIC)'!F199 -> 0 | M200: ='Project Information'!$B$11*'Filters (EPIC)'!G199 -> 0 | N200: ='Project Information'!$B$12*'Filters (EPIC)'!H199 -> 0 | O200: ='Project Information'!$B$13*'Filters (EPIC)'!I199 -> 0 | P200: ='Project Information'!$B$14*'Filters (EPIC)'!J199 -> 0 | Q200: ='Project Information'!$B$15*'Filters (EPIC)'!K199 -> 0 | R200: ='Project Information'!$B$16*'Filters (EPIC)'!L199 -> 0 | S200: ='Project Information'!$B$17*'Filters (EPIC)'!M199 -> 0 | T200: ='Project Information'!$B$18*'Filters (EPIC)'!N199 -> 0 | U200: ='Project Information'!$B$19*'Filters (EPIC)'!O199 -> 0 | V200: ='Project Information'!$B$20*'Filters (EPIC)'!P199 -> 0 | W200: ='Project Information'!$B$21*'Filters (EPIC)'!Q199 -> 0 | X200: ='Project Information'!$B$22*'Filters (EPIC)'!R199 -> 0 | Y200: ='Project Information'!$B$23*'Filters (EPIC)'!S199 -> 0 | Z200: =OR(COUNTIF(H200:Y200,1)>0) -> FALSE
A201: FALSE | B201: FALSE | C201: FALSE | D201: Power Distribution Diagrams and Risers | E201: Power Distribution Diagrams | F201: Generator sizing accounts for de-rating factors for high ambient temperature, high elevation, nonlinear loads, fuel source deviations | G201: If either is selected (Exterior OR Interior Generator Room) on this one | H201: ='Project Information'!$B$6*'Filters (EPIC)'!B200 -> 0 | I201: ='Project Information'!$B$7*'Filters (EPIC)'!C200 -> 0 | J201: ='Project Information'!$B$8*'Filters (EPIC)'!D200 -> 0 | K201: ='Project Information'!$B$9*'Filters (EPIC)'!E200 -> 0 | L201: ='Project Information'!$B$10*'Filters (EPIC)'!F200 -> 0 | M201: ='Project Information'!$B$11*'Filters (EPIC)'!G200 -> 0 | N201: ='Project Information'!$B$12*'Filters (EPIC)'!H200 -> 0 | O201: ='Project Information'!$B$13*'Filters (EPIC)'!I200 -> 0 | P201: ='Project Information'!$B$14*'Filters (EPIC)'!J200 -> 0 | Q201: ='Project Information'!$B$15*'Filters (EPIC)'!K200 -> 0 | R201: ='Project Information'!$B$16*'Filters (EPIC)'!L200 -> 0 | S201: ='Project Information'!$B$17*'Filters (EPIC)'!M200 -> 0 | T201: ='Project Information'!$B$18*'Filters (EPIC)'!N200 -> 0 | U201: ='Project Information'!$B$19*'Filters (EPIC)'!O200 -> 0 | V201: ='Project Information'!$B$20*'Filters (EPIC)'!P200 -> 0 | W201: ='Project Information'!$B$21*'Filters (EPIC)'!Q200 -> 0 | X201: ='Project Information'!$B$22*'Filters (EPIC)'!R200 -> 0 | Y201: ='Project Information'!$B$23*'Filters (EPIC)'!S200 -> 0 | Z201: =OR(COUNTIF(H201:Y201,1)>0) -> FALSE
A202: FALSE | B202: FALSE | C202: FALSE | D202: Power Distribution Diagrams and Risers | E202: Power Distribution Diagrams | F202: Surge protection devices are indicated for preliminary issue packages until panel schedules are included in issue package (identify whether internally or externally mounted, coordinate with spec) | H202: ='Project Information'!$B$6*'Filters (EPIC)'!B201 -> 1 | I202: ='Project Information'!$B$7*'Filters (EPIC)'!C201 -> 0 | J202: ='Project Information'!$B$8*'Filters (EPIC)'!D201 -> 0 | K202: ='Project Information'!$B$9*'Filters (EPIC)'!E201 -> 0 | L202: ='Project Information'!$B$10*'Filters (EPIC)'!F201 -> 0 | M202: ='Project Information'!$B$11*'Filters (EPIC)'!G201 -> 0 | N202: ='Project Information'!$B$12*'Filters (EPIC)'!H201 -> 0 | O202: ='Project Information'!$B$13*'Filters (EPIC)'!I201 -> 0 | P202: ='Project Information'!$B$14*'Filters (EPIC)'!J201 -> 0 | Q202: ='Project Information'!$B$15*'Filters (EPIC)'!K201 -> 0 | R202: ='Project Information'!$B$16*'Filters (EPIC)'!L201 -> 0 | S202: ='Project Information'!$B$17*'Filters (EPIC)'!M201 -> 0 | T202: ='Project Information'!$B$18*'Filters (EPIC)'!N201 -> 0 | U202: ='Project Information'!$B$19*'Filters (EPIC)'!O201 -> 0 | V202: ='Project Information'!$B$20*'Filters (EPIC)'!P201 -> 0 | W202: ='Project Information'!$B$21*'Filters (EPIC)'!Q201 -> 0 | X202: ='Project Information'!$B$22*'Filters (EPIC)'!R201 -> 0 | Y202: ='Project Information'!$B$23*'Filters (EPIC)'!S201 -> 0 | Z202: =OR(COUNTIF(H202:Y202,1)>0) -> TRUE
A203: FALSE | B203: FALSE | C203: FALSE | D203: Power Distribution Diagrams and Risers | E203: Power Distribution Diagrams | F203: Transformer sizes are indicated | H203: ='Project Information'!$B$6*'Filters (EPIC)'!B202 -> 1 | I203: ='Project Information'!$B$7*'Filters (EPIC)'!C202 -> 0 | J203: ='Project Information'!$B$8*'Filters (EPIC)'!D202 -> 0 | K203: ='Project Information'!$B$9*'Filters (EPIC)'!E202 -> 0 | L203: ='Project Information'!$B$10*'Filters (EPIC)'!F202 -> 0 | M203: ='Project Information'!$B$11*'Filters (EPIC)'!G202 -> 0 | N203: ='Project Information'!$B$12*'Filters (EPIC)'!H202 -> 0 | O203: ='Project Information'!$B$13*'Filters (EPIC)'!I202 -> 0 | P203: ='Project Information'!$B$14*'Filters (EPIC)'!J202 -> 0 | Q203: ='Project Information'!$B$15*'Filters (EPIC)'!K202 -> 0 | R203: ='Project Information'!$B$16*'Filters (EPIC)'!L202 -> 0 | S203: ='Project Information'!$B$17*'Filters (EPIC)'!M202 -> 0 | T203: ='Project Information'!$B$18*'Filters (EPIC)'!N202 -> 0 | U203: ='Project Information'!$B$19*'Filters (EPIC)'!O202 -> 0 | V203: ='Project Information'!$B$20*'Filters (EPIC)'!P202 -> 0 | W203: ='Project Information'!$B$21*'Filters (EPIC)'!Q202 -> 0 | X203: ='Project Information'!$B$22*'Filters (EPIC)'!R202 -> 0 | Y203: ='Project Information'!$B$23*'Filters (EPIC)'!S202 -> 0 | Z203: =OR(COUNTIF(H203:Y203,1)>0) -> TRUE
A204: FALSE | B204: FALSE | C204: FALSE | D204: Power Distribution Diagrams and Risers | E204: Power Distribution Diagrams | F204: Special transformer configurations are indicated (i.e. proper K rating indicated, phase shifting, etc.) | H204: ='Project Information'!$B$6*'Filters (EPIC)'!B203 -> 1 | I204: ='Project Information'!$B$7*'Filters (EPIC)'!C203 -> 0 | J204: ='Project Information'!$B$8*'Filters (EPIC)'!D203 -> 0 | K204: ='Project Information'!$B$9*'Filters (EPIC)'!E203 -> 0 | L204: ='Project Information'!$B$10*'Filters (EPIC)'!F203 -> 0 | M204: ='Project Information'!$B$11*'Filters (EPIC)'!G203 -> 0 | N204: ='Project Information'!$B$12*'Filters (EPIC)'!H203 -> 0 | O204: ='Project Information'!$B$13*'Filters (EPIC)'!I203 -> 0 | P204: ='Project Information'!$B$14*'Filters (EPIC)'!J203 -> 0 | Q204: ='Project Information'!$B$15*'Filters (EPIC)'!K203 -> 0 | R204: ='Project Information'!$B$16*'Filters (EPIC)'!L203 -> 0 | S204: ='Project Information'!$B$17*'Filters (EPIC)'!M203 -> 0 | T204: ='Project Information'!$B$18*'Filters (EPIC)'!N203 -> 0 | U204: ='Project Information'!$B$19*'Filters (EPIC)'!O203 -> 0 | V204: ='Project Information'!$B$20*'Filters (EPIC)'!P203 -> 0 | W204: ='Project Information'!$B$21*'Filters (EPIC)'!Q203 -> 0 | X204: ='Project Information'!$B$22*'Filters (EPIC)'!R203 -> 0 | Y204: ='Project Information'!$B$23*'Filters (EPIC)'!S203 -> 0 | Z204: =OR(COUNTIF(H204:Y204,1)>0) -> TRUE
A205: FALSE | B205: FALSE | C205: FALSE | D205: Power Distribution Diagrams and Risers | E205: Power Distribution Diagrams | F205: Customer metering points are indicated, and specifications included regarding interface with BAS. Method for isolation of loads by type for metering purposes is clear (panel level, circuit level, etc.) Identify all submeters which may be required for load summary and/or tenant loads. | H205: ='Project Information'!$B$6*'Filters (EPIC)'!B204 -> 1 | I205: ='Project Information'!$B$7*'Filters (EPIC)'!C204 -> 0 | J205: ='Project Information'!$B$8*'Filters (EPIC)'!D204 -> 0 | K205: ='Project Information'!$B$9*'Filters (EPIC)'!E204 -> 0 | L205: ='Project Information'!$B$10*'Filters (EPIC)'!F204 -> 0 | M205: ='Project Information'!$B$11*'Filters (EPIC)'!G204 -> 0 | N205: ='Project Information'!$B$12*'Filters (EPIC)'!H204 -> 0 | O205: ='Project Information'!$B$13*'Filters (EPIC)'!I204 -> 0 | P205: ='Project Information'!$B$14*'Filters (EPIC)'!J204 -> 0 | Q205: ='Project Information'!$B$15*'Filters (EPIC)'!K204 -> 0 | R205: ='Project Information'!$B$16*'Filters (EPIC)'!L204 -> 0 | S205: ='Project Information'!$B$17*'Filters (EPIC)'!M204 -> 0 | T205: ='Project Information'!$B$18*'Filters (EPIC)'!N204 -> 0 | U205: ='Project Information'!$B$19*'Filters (EPIC)'!O204 -> 0 | V205: ='Project Information'!$B$20*'Filters (EPIC)'!P204 -> 0 | W205: ='Project Information'!$B$21*'Filters (EPIC)'!Q204 -> 0 | X205: ='Project Information'!$B$22*'Filters (EPIC)'!R204 -> 0 | Y205: ='Project Information'!$B$23*'Filters (EPIC)'!S204 -> 0 | Z205: =OR(COUNTIF(H205:Y205,1)>0) -> TRUE
A206: FALSE | B206: FALSE | C206: FALSE | D206: Power Distribution Diagrams and Risers | E206: Power Distribution Diagrams | F206: Utility metering is indicated | H206: ='Project Information'!$B$6*'Filters (EPIC)'!B205 -> 0 | I206: ='Project Information'!$B$7*'Filters (EPIC)'!C205 -> 0 | J206: ='Project Information'!$B$8*'Filters (EPIC)'!D205 -> 0 | K206: ='Project Information'!$B$9*'Filters (EPIC)'!E205 -> 0 | L206: ='Project Information'!$B$10*'Filters (EPIC)'!F205 -> 0 | M206: ='Project Information'!$B$11*'Filters (EPIC)'!G205 -> 0 | N206: ='Project Information'!$B$12*'Filters (EPIC)'!H205 -> 0 | O206: ='Project Information'!$B$13*'Filters (EPIC)'!I205 -> 0 | P206: ='Project Information'!$B$14*'Filters (EPIC)'!J205 -> 0 | Q206: ='Project Information'!$B$15*'Filters (EPIC)'!K205 -> 0 | R206: ='Project Information'!$B$16*'Filters (EPIC)'!L205 -> 0 | S206: ='Project Information'!$B$17*'Filters (EPIC)'!M205 -> 0 | T206: ='Project Information'!$B$18*'Filters (EPIC)'!N205 -> 0 | U206: ='Project Information'!$B$19*'Filters (EPIC)'!O205 -> 0 | V206: ='Project Information'!$B$20*'Filters (EPIC)'!P205 -> 0 | W206: ='Project Information'!$B$21*'Filters (EPIC)'!Q205 -> 0 | X206: ='Project Information'!$B$22*'Filters (EPIC)'!R205 -> 0 | Y206: ='Project Information'!$B$23*'Filters (EPIC)'!S205 -> 0 | Z206: =OR(COUNTIF(H206:Y206,1)>0) -> FALSE
A207: FALSE | B207: FALSE | C207: FALSE | D207: Power Distribution Diagrams and Risers | E207: Power Distribution Diagrams | F207: Where protective devices with relays are required, desired functions to be programmed are clearly defined | H207: ='Project Information'!$B$6*'Filters (EPIC)'!B206 -> 1 | I207: ='Project Information'!$B$7*'Filters (EPIC)'!C206 -> 0 | J207: ='Project Information'!$B$8*'Filters (EPIC)'!D206 -> 0 | K207: ='Project Information'!$B$9*'Filters (EPIC)'!E206 -> 0 | L207: ='Project Information'!$B$10*'Filters (EPIC)'!F206 -> 0 | M207: ='Project Information'!$B$11*'Filters (EPIC)'!G206 -> 0 | N207: ='Project Information'!$B$12*'Filters (EPIC)'!H206 -> 0 | O207: ='Project Information'!$B$13*'Filters (EPIC)'!I206 -> 0 | P207: ='Project Information'!$B$14*'Filters (EPIC)'!J206 -> 0 | Q207: ='Project Information'!$B$15*'Filters (EPIC)'!K206 -> 0 | R207: ='Project Information'!$B$16*'Filters (EPIC)'!L206 -> 0 | S207: ='Project Information'!$B$17*'Filters (EPIC)'!M206 -> 0 | T207: ='Project Information'!$B$18*'Filters (EPIC)'!N206 -> 0 | U207: ='Project Information'!$B$19*'Filters (EPIC)'!O206 -> 0 | V207: ='Project Information'!$B$20*'Filters (EPIC)'!P206 -> 0 | W207: ='Project Information'!$B$21*'Filters (EPIC)'!Q206 -> 0 | X207: ='Project Information'!$B$22*'Filters (EPIC)'!R206 -> 0 | Y207: ='Project Information'!$B$23*'Filters (EPIC)'!S206 -> 0 | Z207: =OR(COUNTIF(H207:Y207,1)>0) -> TRUE
A208: FALSE | B208: FALSE | C208: FALSE | D208: Power Distribution Diagrams and Risers | E208: Power Distribution Diagrams | F208: Ground fault protection is properly indicated for normal service (i.e. two levels for healthcare); per NEC 230 and 215. | H208: ='Project Information'!$B$6*'Filters (EPIC)'!B207 -> 1 | I208: ='Project Information'!$B$7*'Filters (EPIC)'!C207 -> 0 | J208: ='Project Information'!$B$8*'Filters (EPIC)'!D207 -> 0 | K208: ='Project Information'!$B$9*'Filters (EPIC)'!E207 -> 0 | L208: ='Project Information'!$B$10*'Filters (EPIC)'!F207 -> 0 | M208: ='Project Information'!$B$11*'Filters (EPIC)'!G207 -> 0 | N208: ='Project Information'!$B$12*'Filters (EPIC)'!H207 -> 0 | O208: ='Project Information'!$B$13*'Filters (EPIC)'!I207 -> 0 | P208: ='Project Information'!$B$14*'Filters (EPIC)'!J207 -> 0 | Q208: ='Project Information'!$B$15*'Filters (EPIC)'!K207 -> 0 | R208: ='Project Information'!$B$16*'Filters (EPIC)'!L207 -> 0 | S208: ='Project Information'!$B$17*'Filters (EPIC)'!M207 -> 0 | T208: ='Project Information'!$B$18*'Filters (EPIC)'!N207 -> 0 | U208: ='Project Information'!$B$19*'Filters (EPIC)'!O207 -> 0 | V208: ='Project Information'!$B$20*'Filters (EPIC)'!P207 -> 0 | W208: ='Project Information'!$B$21*'Filters (EPIC)'!Q207 -> 0 | X208: ='Project Information'!$B$22*'Filters (EPIC)'!R207 -> 0 | Y208: ='Project Information'!$B$23*'Filters (EPIC)'!S207 -> 0 | Z208: =OR(COUNTIF(H208:Y208,1)>0) -> TRUE
A209: FALSE | B209: FALSE | C209: FALSE | D209: Power Distribution Diagrams and Risers | E209: Power Distribution Diagrams | F209: Conductor quantity is correctly indicated (i.e. 'N' subscript for three wire circuits, 'G' subscript for service entrance) | H209: ='Project Information'!$B$6*'Filters (EPIC)'!B208 -> 1 | I209: ='Project Information'!$B$7*'Filters (EPIC)'!C208 -> 0 | J209: ='Project Information'!$B$8*'Filters (EPIC)'!D208 -> 0 | K209: ='Project Information'!$B$9*'Filters (EPIC)'!E208 -> 0 | L209: ='Project Information'!$B$10*'Filters (EPIC)'!F208 -> 0 | M209: ='Project Information'!$B$11*'Filters (EPIC)'!G208 -> 0 | N209: ='Project Information'!$B$12*'Filters (EPIC)'!H208 -> 0 | O209: ='Project Information'!$B$13*'Filters (EPIC)'!I208 -> 0 | P209: ='Project Information'!$B$14*'Filters (EPIC)'!J208 -> 0 | Q209: ='Project Information'!$B$15*'Filters (EPIC)'!K208 -> 0 | R209: ='Project Information'!$B$16*'Filters (EPIC)'!L208 -> 0 | S209: ='Project Information'!$B$17*'Filters (EPIC)'!M208 -> 0 | T209: ='Project Information'!$B$18*'Filters (EPIC)'!N208 -> 0 | U209: ='Project Information'!$B$19*'Filters (EPIC)'!O208 -> 0 | V209: ='Project Information'!$B$20*'Filters (EPIC)'!P208 -> 0 | W209: ='Project Information'!$B$21*'Filters (EPIC)'!Q208 -> 0 | X209: ='Project Information'!$B$22*'Filters (EPIC)'!R208 -> 0 | Y209: ='Project Information'!$B$23*'Filters (EPIC)'!S208 -> 0 | Z209: =OR(COUNTIF(H209:Y209,1)>0) -> TRUE
A210: FALSE | B210: FALSE | C210: FALSE | D210: Power Distribution Diagrams and Risers | E210: Power Distribution Diagrams | F210: Circuits requiring 2 hour protection are identified (i.e. emergency feeders NEC 700.10 routed above ceilings, fire pump feeders NEC 695.6, circuits serving stair pressurization fans, generator control wiring (i.e. AIS to generator) | H210: ='Project Information'!$B$6*'Filters (EPIC)'!B209 -> 1 | I210: ='Project Information'!$B$7*'Filters (EPIC)'!C209 -> 0 | J210: ='Project Information'!$B$8*'Filters (EPIC)'!D209 -> 0 | K210: ='Project Information'!$B$9*'Filters (EPIC)'!E209 -> 0 | L210: ='Project Information'!$B$10*'Filters (EPIC)'!F209 -> 0 | M210: ='Project Information'!$B$11*'Filters (EPIC)'!G209 -> 0 | N210: ='Project Information'!$B$12*'Filters (EPIC)'!H209 -> 0 | O210: ='Project Information'!$B$13*'Filters (EPIC)'!I209 -> 0 | P210: ='Project Information'!$B$14*'Filters (EPIC)'!J209 -> 0 | Q210: ='Project Information'!$B$15*'Filters (EPIC)'!K209 -> 0 | R210: ='Project Information'!$B$16*'Filters (EPIC)'!L209 -> 0 | S210: ='Project Information'!$B$17*'Filters (EPIC)'!M209 -> 0 | T210: ='Project Information'!$B$18*'Filters (EPIC)'!N209 -> 0 | U210: ='Project Information'!$B$19*'Filters (EPIC)'!O209 -> 0 | V210: ='Project Information'!$B$20*'Filters (EPIC)'!P209 -> 0 | W210: ='Project Information'!$B$21*'Filters (EPIC)'!Q209 -> 0 | X210: ='Project Information'!$B$22*'Filters (EPIC)'!R209 -> 0 | Y210: ='Project Information'!$B$23*'Filters (EPIC)'!S209 -> 0 | Z210: =OR(COUNTIF(H210:Y210,1)>0) -> TRUE
A211: FALSE | B211: FALSE | C211: FALSE | D211: Power Distribution Diagrams and Risers | E211: Power Distribution Diagrams | F211: Fire pump service configuration is code compliant | H211: ='Project Information'!$B$6*'Filters (EPIC)'!B210 -> 0 | I211: ='Project Information'!$B$7*'Filters (EPIC)'!C210 -> 0 | J211: ='Project Information'!$B$8*'Filters (EPIC)'!D210 -> 0 | K211: ='Project Information'!$B$9*'Filters (EPIC)'!E210 -> 0 | L211: ='Project Information'!$B$10*'Filters (EPIC)'!F210 -> 0 | M211: ='Project Information'!$B$11*'Filters (EPIC)'!G210 -> 0 | N211: ='Project Information'!$B$12*'Filters (EPIC)'!H210 -> 0 | O211: ='Project Information'!$B$13*'Filters (EPIC)'!I210 -> 0 | P211: ='Project Information'!$B$14*'Filters (EPIC)'!J210 -> 0 | Q211: ='Project Information'!$B$15*'Filters (EPIC)'!K210 -> 0 | R211: ='Project Information'!$B$16*'Filters (EPIC)'!L210 -> 0 | S211: ='Project Information'!$B$17*'Filters (EPIC)'!M210 -> 0 | T211: ='Project Information'!$B$18*'Filters (EPIC)'!N210 -> 0 | U211: ='Project Information'!$B$19*'Filters (EPIC)'!O210 -> 0 | V211: ='Project Information'!$B$20*'Filters (EPIC)'!P210 -> 0 | W211: ='Project Information'!$B$21*'Filters (EPIC)'!Q210 -> 0 | X211: ='Project Information'!$B$22*'Filters (EPIC)'!R210 -> 0 | Y211: ='Project Information'!$B$23*'Filters (EPIC)'!S210 -> 0 | Z211: =OR(COUNTIF(H211:Y211,1)>0) -> FALSE
A212: FALSE | B212: FALSE | C212: FALSE | D212: Power Distribution Diagrams and Risers | E212: Power Distribution Diagrams | F212: Fire pump controller to motor connection is properly sized/identified (i.e. 6 conductors at 58% for wye-delta starter configuration) | H212: ='Project Information'!$B$6*'Filters (EPIC)'!B211 -> 0 | I212: ='Project Information'!$B$7*'Filters (EPIC)'!C211 -> 0 | J212: ='Project Information'!$B$8*'Filters (EPIC)'!D211 -> 0 | K212: ='Project Information'!$B$9*'Filters (EPIC)'!E211 -> 0 | L212: ='Project Information'!$B$10*'Filters (EPIC)'!F211 -> 0 | M212: ='Project Information'!$B$11*'Filters (EPIC)'!G211 -> 0 | N212: ='Project Information'!$B$12*'Filters (EPIC)'!H211 -> 0 | O212: ='Project Information'!$B$13*'Filters (EPIC)'!I211 -> 0 | P212: ='Project Information'!$B$14*'Filters (EPIC)'!J211 -> 0 | Q212: ='Project Information'!$B$15*'Filters (EPIC)'!K211 -> 0 | R212: ='Project Information'!$B$16*'Filters (EPIC)'!L211 -> 0 | S212: ='Project Information'!$B$17*'Filters (EPIC)'!M211 -> 0 | T212: ='Project Information'!$B$18*'Filters (EPIC)'!N211 -> 0 | U212: ='Project Information'!$B$19*'Filters (EPIC)'!O211 -> 0 | V212: ='Project Information'!$B$20*'Filters (EPIC)'!P211 -> 0 | W212: ='Project Information'!$B$21*'Filters (EPIC)'!Q211 -> 0 | X212: ='Project Information'!$B$22*'Filters (EPIC)'!R211 -> 0 | Y212: ='Project Information'!$B$23*'Filters (EPIC)'!S211 -> 0 | Z212: =OR(COUNTIF(H212:Y212,1)>0) -> FALSE
A213: FALSE | B213: FALSE | C213: FALSE | D213: Power Distribution Diagrams and Risers | E213: Power Distribution Diagrams | F213: Breaker de-rating indicated, if needed (i.e. insulated case breakers with X/R rating greater than 6.6) | H213: ='Project Information'!$B$6*'Filters (EPIC)'!B212 -> 1 | I213: ='Project Information'!$B$7*'Filters (EPIC)'!C212 -> 0 | J213: ='Project Information'!$B$8*'Filters (EPIC)'!D212 -> 0 | K213: ='Project Information'!$B$9*'Filters (EPIC)'!E212 -> 0 | L213: ='Project Information'!$B$10*'Filters (EPIC)'!F212 -> 0 | M213: ='Project Information'!$B$11*'Filters (EPIC)'!G212 -> 0 | N213: ='Project Information'!$B$12*'Filters (EPIC)'!H212 -> 0 | O213: ='Project Information'!$B$13*'Filters (EPIC)'!I212 -> 0 | P213: ='Project Information'!$B$14*'Filters (EPIC)'!J212 -> 0 | Q213: ='Project Information'!$B$15*'Filters (EPIC)'!K212 -> 0 | R213: ='Project Information'!$B$16*'Filters (EPIC)'!L212 -> 0 | S213: ='Project Information'!$B$17*'Filters (EPIC)'!M212 -> 0 | T213: ='Project Information'!$B$18*'Filters (EPIC)'!N212 -> 0 | U213: ='Project Information'!$B$19*'Filters (EPIC)'!O212 -> 0 | V213: ='Project Information'!$B$20*'Filters (EPIC)'!P212 -> 0 | W213: ='Project Information'!$B$21*'Filters (EPIC)'!Q212 -> 0 | X213: ='Project Information'!$B$22*'Filters (EPIC)'!R212 -> 0 | Y213: ='Project Information'!$B$23*'Filters (EPIC)'!S212 -> 0 | Z213: =OR(COUNTIF(H213:Y213,1)>0) -> TRUE
... A349: FALSE | B349: FALSE | C349: FALSE | D349: Other Systems | E349: Emergency Radio Communication System | F349: System schematic is provided | H349: ='Project Information'!$B$6*'Filters (EPIC)'!B348 -> 0 | I349: ='Project Information'!$B$7*'Filters (EPIC)'!C348 -> 0 | J349: ='Project Information'!$B$8*'Filters (EPIC)'!D348 -> 0 | K349: ='Project Information'!$B$9*'Filters (EPIC)'!E348 -> 0 | L349: ='Project Information'!$B$10*'Filters (EPIC)'!F348 -> 0 | M349: ='Project Information'!$B$11*'Filters (EPIC)'!G348 -> 0 | N349: ='Project Information'!$B$12*'Filters (EPIC)'!H348 -> 0 | O349: ='Project Information'!$B$13*'Filters (EPIC)'!I348 -> 0 | P349: ='Project Information'!$B$14*'Filters (EPIC)'!J348 -> 0 | Q349: ='Project Information'!$B$15*'Filters (EPIC)'!K348 -> 0 | R349: ='Project Information'!$B$16*'Filters (EPIC)'!L348 -> 0 | S349: ='Project Information'!$B$17*'Filters (EPIC)'!M348 -> 0 | T349: ='Project Information'!$B$18*'Filters (EPIC)'!N348 -> 0 | U349: ='Project Information'!$B$19*'Filters (EPIC)'!O348 -> 0 | V349: ='Project Information'!$B$20*'Filters (EPIC)'!P348 -> 0 | W349: ='Project Information'!$B$21*'Filters (EPIC)'!Q348 -> 0 | X349: ='Project Information'!$B$22*'Filters (EPIC)'!R348 -> 0 | Y349: ='Project Information'!$B$23*'Filters (EPIC)'!S348 -> 0 | Z349: =OR(COUNTIF(H349:Y349,1)>0) -> FALSE

Sheet Project Information
A1: Project Information
A2: Project Name: | B2: EXAMPLE PROJECT NAME
A3: Project Number: | B3: 25999999
A4: Date: | B4: 45950
A5: Project Filters Select ALL That Are Applicable
A6: Standard | B6: TRUE
A7: Healthcare | B7: FALSE
A8: Sports | B8: FALSE
A9: Site Plan | B9: FALSE
A10: Food Service / Kitchen | B10: FALSE
A11: Demolition / Renovation | B11: FALSE
A12: Utility Service Entrance | B12: FALSE
A13: Duct Bank (Feeder or Utility Service Entrance) | B13: FALSE
A14: ATS | B14: FALSE
A15: Exterior Generator or Fuel Tank | B15: FALSE
A16: Indoor Generator Room | B16: FALSE
A17: Exterior Lighting | B17: FALSE
... A23: Fire Alarm | B23: FALSE

Sheet Filters (EPIC)
B1: Filters
B2: Standard | C2: Healthcare | D2: Sports | E2: Site Plan | F2: Food Service / Kitchen | G2: Demolition / Renovation | H2: Utility Service Entrance | I2: Duct Bank (Feeder or Utility Service Entrance) | J2: ATS | K2: Exterior Generator or Fuel Tank | L2: Indoor Generator Room | M2: Exterior Lighting | N2: Helipad | O2: Elevator / Escalator | P2: Fire Pump | Q2: Fire Command Center | R2: Emergency Radio Communication System | S2: Fire Alarm
A3: ='Electrical QC Checklist'!F4 -> All applicable specification sections included | B3: 1
A4: ='Electrical QC Checklist'!F5 -> Specifications are edited for project specific scope | B4: 1
A5: ='Electrical QC Checklist'!F6 -> Specifications identify applicable codes including energy code(s) | B5: 1
A6: ='Electrical QC Checklist'!F7 -> Specifications for conductors (copper, aluminum, or both) are consistent with schedules and owner direction | B6: 1
A7: ='Electrical QC Checklist'!F8 -> Construction sequence / phasing is considered and temporary electrical equipment or requirements are identified. | G7: 1
A8: ='Electrical QC Checklist'!F9 -> Existing to remain, existing to be removed, new work is clearly identified | G8: 1
A9: ='Electrical QC Checklist'!F10 -> Standard ICRA notes are included for healthcare projects | C9: 1
A10: ='Electrical QC Checklist'!F11 -> Demolition plans clearly identify equipment/scope as “existing to remain” or “existing to be removed” | G10: 1
A11: ='Electrical QC Checklist'!F12 -> Equipment to be turned over to Owner is defined | G11: 1
A12: ='Electrical QC Checklist'!F13 -> Requirements for bracing and certification are designated based on building location, use, seismic category and importance factor | B12: 1
A13: ='Electrical QC Checklist'!F14 -> For hurricane zones, design wind speeds for risk category III and IV building are designated for exterior lighting, helipad lighting , and PV systems | B13: 1
A14: ='Electrical QC Checklist'!F15 -> For high ambient temperature areas, capacity of generators and/or exterior transformers has been derated | B14: 1
A15: ='Electrical QC Checklist'!F16 -> For high altitude areas, capacity of generators and/or exterior transformers has been derated | B15: 1
A16: ='Electrical QC Checklist'!F17 -> For corrosive environments, equipment construction is specified appropriately | B16: 1
A17: ='Electrical QC Checklist'!F18 -> Standard feeder schedule is used. Use of aluminum, if shown, matches specification requirements | B17: 1
A18: ='Electrical QC Checklist'!F19 -> Standard transformer schedule is used. Use of aluminum conductors and/or windings, if shown, matches specification requirements | B18: 1
A19: ='Electrical QC Checklist'!F20 -> Standard Automatic Transfer Switch schedule is used and completed | J19: 1
A20: ='Electrical QC Checklist'!F21 -> Available fault current fields are completed | J20: 1
A21: ='Electrical QC Checklist'!F22 -> Priority levels with time delays are assigned | J21: 1
A22: ='Electrical QC Checklist'!F23 -> Mechanical equipment connection schedule is complete | B22: 1
A23: ='Electrical QC Checklist'!F24 -> Elevator/escalator connection schedule is complete | O23: 1
A24: ='Electrical QC Checklist'!F25 -> Vendor Equipment connection schedule is complete | B24: 1
A25: ='Electrical QC Checklist'!F26 -> Food service connection schedules are complete | F25: 1
A26: ='Electrical QC Checklist'!F27 -> Lab equipment connection schedule is complete | B26: 1
A27: ='Electrical QC Checklist'!F28 -> Schedule provided for each panelboard and distribution panel on distribution diagram | B27: 1
A28: ='Electrical QC Checklist'!F29 -> Schedules are complete | B28: 1
A29: ='Electrical QC Checklist'!F30 -> Schedule includes calculated available fault current value and required AIC rating | B29: 1
A30: ='Electrical QC Checklist'!F31 -> Schedule indicates MCB vs. MLO requirements | B30: 1
A31: ='Electrical QC Checklist'!F32 -> Calculated demand load + spare capacity is less than the panel rating and 80% of upstream OCP | B31: 1
A32: ='Electrical QC Checklist'!F33 -> For transformer applications, upstream feeder breaker and downstream main breaker sizing matches transformer schedule | B32: 1
A33: ='Electrical QC Checklist'!F34 -> Schedule indicates required spares and spaces (recommend 20% spare capacity and breaker mounting space) Verify owner specific requirements. | B33: 1
A34: ='Electrical QC Checklist'!F35 -> Schedule enclosure configuration matches proposed location (i.e. surface vs. flush, hazardous, NEMA 1, 3, 4X, etc.) | B34: 1
A35: ='Electrical QC Checklist'!F36 -> Schedule includes 3 pole breaker for connection to SPD. Schedule denotes internal versus external mounting. | B35: 1
A36: ='Electrical QC Checklist'!F37 -> Schedule includes notes for ARMS reduction approach for 1200A and higher breaker sizes per NEC 240.87 | B36: 1
A37: ='Electrical QC Checklist'!F38 -> Schedule type reflects required construction and configuration (i.e. panelboard, distribution panel, MCC, switchboard, isolation) | B37: 1
... A56: ='Electrical QC Checklist'!F57 -> Fixture wattage is indicated with appropriate units (i.e. w/fixture or w/linear foot) | B56: 1
A57: ='Electrical QC Checklist'!F58 -> Electric Company service drop location terminal point, metering is identified | H57: 1
A58: ='Electrical QC Checklist'!F59 -> Utility underground or overhead easement coordinated with civil, where required | H58: 1
...

Sheet Revision Log
A1: Revision Date | B1: Description of Change
A2: 45950 | B2: Added Excel version with updated content
